exception MyError ()

fun main() {
  try {
    throw MyError ()
  }
  catch MyError _ {
    print("caught")
  }
}
