exception MyError ()

fun main() {
  try {
    try {
      _unsafe_js("function() { throw 45; }()")
    }
    catch MyError _ {
      print("not here")
    }
  }
  catch _ {
    print("caught")
  }
}
